<sdf version='1.6'>
  <world name='default'>
    <plugin name='hello' filename='libhello.so'/>
    <light name='sun' type='directional'>
      <cast_shadows>1</cast_shadows>
      <pose frame=''>0 0 10 0 -0 0</pose>
      <diffuse>0.8 0.8 0.8 1</diffuse>
      <specular>0.2 0.2 0.2 1</specular>
      <attenuation>
        <range>1000</range>
        <constant>0.9</constant>
        <linear>0.01</linear>
        <quadratic>0.001</quadratic>
      </attenuation>
      <direction>-0.5 0.1 -0.9</direction>
    </light>
    <model name='ground_plane'>
      <static>1</static>
      <link name='link'>
        <collision name='collision'>
          <geometry>
            <plane>
              <normal>0 0 1</normal>
              <size>100 100</size>
            </plane>
          </geometry>
          <surface>
            <contact>
              <collide_bitmask>65535</collide_bitmask>
              <ode/>
            </contact>
            <friction>
              <ode>
                <mu>100</mu>
                <mu2>50</mu2>
              </ode>
              <torsional>
                <ode/>
              </torsional>
            </friction>
            <bounce/>
          </surface>
          <max_contacts>10</max_contacts>
        </collision>
        <visual name='visual'>
          <cast_shadows>0</cast_shadows>
          <geometry>
            <plane>
              <normal>0 0 1</normal>
              <size>100 100</size>
            </plane>
          </geometry>
          <material>
            <script>
              <uri>file://media/materials/scripts/gazebo.material</uri>
              <name>Gazebo/Grey</name>
            </script>
          </material>
        </visual>
        <self_collide>0</self_collide>
        <kinematic>0</kinematic>
      </link>
    </model>
    <gravity>0 0 -9.8</gravity>
    <magnetic_field>6e-06 2.3e-05 -4.2e-05</magnetic_field>
    <atmosphere type='adiabatic'/>
    <physics name='default_physics' default='0' type='ode'>
      <max_step_size>0.001</max_step_size>
      <real_time_factor>1</real_time_factor>
      <real_time_update_rate>1000</real_time_update_rate>
    </physics>
    <scene>
      <ambient>0.4 0.4 0.4 1</ambient>
      <background>0.7 0.7 0.7 1</background>
      <shadows>1</shadows>
    </scene>
    <spherical_coordinates>
      <surface_model>EARTH_WGS84</surface_model>
      <latitude_deg>0</latitude_deg>
      <longitude_deg>0</longitude_deg>
      <elevation>0</elevation>
      <heading_deg>0</heading_deg>
    </spherical_coordinates>
    <model name='myroom'>
      <pose frame=''>-7.89984 2.7708 0 0 -0 0</pose>
      <link name='Wall_15'>
        <pose frame=''>-4.425 0 0 0 0 -1.5708</pose>
        <visual name='Wall_15_Visual_0'>
          <pose frame=''>-2.7905 0 1.25 0 -0 0</pose>
          <geometry>
            <box>
              <size>4.169 0.15 2.5</size>
            </box>
          </geometry>
          <material>
            <script>
              <uri>file://media/materials/scripts/gazebo.material</uri>
              <name>Gazebo/CeilingTiled</name>
            </script>
            <ambient>0.996078 0.47451 0.0196078 1</ambient>
          </material>
          <meta>
            <layer>0</layer>
          </meta>
        </visual>
        <collision name='Wall_15_Collision_0'>
          <geometry>
            <box>
              <size>4.169 0.15 2.5</size>
            </box>
          </geometry>
          <pose frame=''>-2.7905 0 1.25 0 -0 0</pose>
          <max_contacts>10</max_contacts>
          <surface>
            <contact>
              <ode/>
            </contact>
            <bounce/>
            <friction>
              <torsional>
                <ode/>
              </torsional>
              <ode/>
            </friction>
          </surface>
        </collision>
        <visual name='Wall_15_Visual_1'>
          <pose frame=''>2.0845 0 0.25 0 -0 0</pose>
          <geometry>
            <box>
              <size>5.581 0.15 0.5</size>
            </box>
          </geometry>
          <material>
            <script>
              <uri>file://media/materials/scripts/gazebo.material</uri>
              <name>Gazebo/CeilingTiled</name>
            </script>
            <ambient>0.996078 0.47451 0.0196078 1</ambient>
          </material>
          <meta>
            <layer>0</layer>
          </meta>
        </visual>
        <collision name='Wall_15_Collision_1'>
          <geometry>
            <box>
              <size>5.581 0.15 0.5</size>
            </box>
          </geometry>
          <pose frame=''>2.0845 0 0.25 0 -0 0</pose>
          <max_contacts>10</max_contacts>
          <surface>
            <contact>
              <ode/>
            </contact>
            <bounce/>
            <friction>
              <torsional>
                <ode/>
              </torsional>
              <ode/>
            </friction>
          </surface>
        </collision>
        <visual name='Wall_15_Visual_2'>
          <pose frame=''>2.4845 0 1.5 0 -0 0</pose>
          <geometry>
            <box>
              <size>4.781 0.15 2</size>
            </box>
          </geometry>
          <material>
            <script>
              <uri>file://media/materials/scripts/gazebo.material</uri>
              <name>Gazebo/CeilingTiled</name>
            </script>
            <ambient>0.996078 0.47451 0.0196078 1</ambient>
          </material>
          <meta>
            <layer>0</layer>
          </meta>
        </visual>
        <collision name='Wall_15_Collision_2'>
          <geometry>
            <box>
              <size>4.781 0.15 2</size>
            </box>
          </geometry>
          <pose frame=''>2.4845 0 1.5 0 -0 0</pose>
          <max_contacts>10</max_contacts>
          <surface>
            <contact>
              <ode/>
            </contact>
            <bounce/>
            <friction>
              <torsional>
                <ode/>
              </torsional>
              <ode/>
            </friction>
          </surface>
        </collision>
        <visual name='Wall_15_Visual_3'>
          <pose frame=''>-0.306001 0 1.9 0 -0 0</pose>
          <geometry>
            <box>
              <size>0.8 0.15 1.2</size>
            </box>
          </geometry>
          <material>
            <script>
              <uri>file://media/materials/scripts/gazebo.material</uri>
              <name>Gazebo/CeilingTiled</name>
            </script>
            <ambient>0.996078 0.47451 0.0196078 1</ambient>
          </material>
          <meta>
            <layer>0</layer>
          </meta>
        </visual>
        <collision name='Wall_15_Collision_3'>
          <geometry>
            <box>
              <size>0.8 0.15 1.2</size>
            </box>
          </geometry>
          <pose frame=''>-0.306001 0 1.9 0 -0 0</pose>
          <max_contacts>10</max_contacts>
          <surface>
            <contact>
              <ode/>
            </contact>
            <bounce/>
            <friction>
              <torsional>
                <ode/>
              </torsional>
              <ode/>
            </friction>
          </surface>
        </collision>
        <self_collide>0</self_collide>
        <kinematic>0</kinematic>
      </link>
      <link name='Wall_16'>
        <pose frame=''>0 -4.8 0 0 -0 0</pose>
        <visual name='Wall_16_Visual_0'>
          <pose frame=''>-3.30817 0 1.25 0 -0 0</pose>
          <geometry>
            <box>
              <size>2.38366 0.15 2.5</size>
            </box>
          </geometry>
          <material>
            <script>
              <uri>file://media/materials/scripts/gazebo.material</uri>
              <name>Gazebo/CeilingTiled</name>
            </script>
            <ambient>0.996078 0.47451 0.0196078 1</ambient>
          </material>
          <meta>
            <layer>0</layer>
          </meta>
        </visual>
        <collision name='Wall_16_Collision_0'>
          <geometry>
            <box>
              <size>2.38366 0.15 2.5</size>
            </box>
          </geometry>
          <pose frame=''>-3.30817 0 1.25 0 -0 0</pose>
          <max_contacts>10</max_contacts>
          <surface>
            <contact>
              <ode/>
            </contact>
            <bounce/>
            <friction>
              <torsional>
                <ode/>
              </torsional>
              <ode/>
            </friction>
          </surface>
        </collision>
        <visual name='Wall_16_Visual_1'>
          <pose frame=''>3.19864 0 1.25 0 -0 0</pose>
          <geometry>
            <box>
              <size>2.60272 0.15 2.5</size>
            </box>
          </geometry>
          <material>
            <script>
              <uri>file://media/materials/scripts/gazebo.material</uri>
              <name>Gazebo/CeilingTiled</name>
            </script>
            <ambient>0.996078 0.47451 0.0196078 1</ambient>
          </material>
          <meta>
            <layer>0</layer>
          </meta>
        </visual>
        <collision name='Wall_16_Collision_1'>
          <geometry>
            <box>
              <size>2.60272 0.15 2.5</size>
            </box>
          </geometry>
          <pose frame=''>3.19864 0 1.25 0 -0 0</pose>
          <max_contacts>10</max_contacts>
          <surface>
            <contact>
              <ode/>
            </contact>
            <bounce/>
            <friction>
              <torsional>
                <ode/>
              </torsional>
              <ode/>
            </friction>
          </surface>
        </collision>
        <visual name='Wall_16_Visual_2'>
          <pose frame=''>-0.559529 0 0.25 0 -0 0</pose>
          <geometry>
            <box>
              <size>3.11363 0.15 0.5</size>
            </box>
          </geometry>
          <material>
            <script>
              <uri>file://media/materials/scripts/gazebo.material</uri>
              <name>Gazebo/CeilingTiled</name>
            </script>
            <ambient>0.996078 0.47451 0.0196078 1</ambient>
          </material>
          <meta>
            <layer>0</layer>
          </meta>
        </visual>
        <collision name='Wall_16_Collision_2'>
          <geometry>
            <box>
              <size>3.11363 0.15 0.5</size>
            </box>
          </geometry>
          <pose frame=''>-0.559529 0 0.25 0 -0 0</pose>
          <max_contacts>10</max_contacts>
          <surface>
            <contact>
              <ode/>
            </contact>
            <bounce/>
            <friction>
              <torsional>
                <ode/>
              </torsional>
              <ode/>
            </friction>
          </surface>
        </collision>
        <visual name='Wall_16_Visual_3'>
          <pose frame=''>-0.159529 0 1.5 0 -0 0</pose>
          <geometry>
            <box>
              <size>2.31363 0.15 2</size>
            </box>
          </geometry>
          <material>
            <script>
              <uri>file://media/materials/scripts/gazebo.material</uri>
              <name>Gazebo/CeilingTiled</name>
            </script>
            <ambient>0.996078 0.47451 0.0196078 1</ambient>
          </material>
          <meta>
            <layer>0</layer>
          </meta>
        </visual>
        <collision name='Wall_16_Collision_3'>
          <geometry>
            <box>
              <size>2.31363 0.15 2</size>
            </box>
          </geometry>
          <pose frame=''>-0.159529 0 1.5 0 -0 0</pose>
          <max_contacts>10</max_contacts>
          <surface>
            <contact>
              <ode/>
            </contact>
            <bounce/>
            <friction>
              <torsional>
                <ode/>
              </torsional>
              <ode/>
            </friction>
          </surface>
        </collision>
        <visual name='Wall_16_Visual_4'>
          <pose frame=''>-1.71634 0 1.9 0 -0 0</pose>
          <geometry>
            <box>
              <size>0.8 0.15 1.2</size>
            </box>
          </geometry>
          <material>
            <script>
              <uri>file://media/materials/scripts/gazebo.material</uri>
              <name>Gazebo/CeilingTiled</name>
            </script>
            <ambient>0.996078 0.47451 0.0196078 1</ambient>
          </material>
          <meta>
            <layer>0</layer>
          </meta>
        </visual>
        <collision name='Wall_16_Collision_4'>
          <geometry>
            <box>
              <size>0.8 0.15 1.2</size>
            </box>
          </geometry>
          <pose frame=''>-1.71634 0 1.9 0 -0 0</pose>
          <max_contacts>10</max_contacts>
          <surface>
            <contact>
              <ode/>
            </contact>
            <bounce/>
            <friction>
              <torsional>
                <ode/>
              </torsional>
              <ode/>
            </friction>
          </surface>
        </collision>
        <visual name='Wall_16_Visual_5'>
          <pose frame=''>1.44728 0 2.25 0 -0 0</pose>
          <geometry>
            <box>
              <size>0.9 0.15 0.5</size>
            </box>
          </geometry>
          <material>
            <script>
              <uri>file://media/materials/scripts/gazebo.material</uri>
              <name>Gazebo/CeilingTiled</name>
            </script>
            <ambient>0.996078 0.47451 0.0196078 1</ambient>
          </material>
          <meta>
            <layer>0</layer>
          </meta>
        </visual>
        <collision name='Wall_16_Collision_5'>
          <geometry>
            <box>
              <size>0.9 0.15 0.5</size>
            </box>
          </geometry>
          <pose frame=''>1.44728 0 2.25 0 -0 0</pose>
          <max_contacts>10</max_contacts>
          <surface>
            <contact>
              <ode/>
            </contact>
            <bounce/>
            <friction>
              <torsional>
                <ode/>
              </torsional>
              <ode/>
            </friction>
          </surface>
        </collision>
        <self_collide>0</self_collide>
        <kinematic>0</kinematic>
      </link>
      <link name='Wall_17'>
        <pose frame=''>4.425 0 0 0 -0 1.5708</pose>
        <visual name='Wall_17_Visual_0'>
          <pose frame=''>-2.45381 0 1.25 0 -0 0</pose>
          <geometry>
            <box>
              <size>4.84237 0.15 2.5</size>
            </box>
          </geometry>
          <material>
            <script>
              <uri>file://media/materials/scripts/gazebo.material</uri>
              <name>Gazebo/CeilingTiled</name>
            </script>
            <ambient>0.996078 0.47451 0.0196078 1</ambient>
          </material>
          <meta>
            <layer>0</layer>
          </meta>
        </visual>
        <collision name='Wall_17_Collision_0'>
          <geometry>
            <box>
              <size>4.84237 0.15 2.5</size>
            </box>
          </geometry>
          <pose frame=''>-2.45381 0 1.25 0 -0 0</pose>
          <max_contacts>10</max_contacts>
          <surface>
            <contact>
              <ode/>
            </contact>
            <bounce/>
            <friction>
              <torsional>
                <ode/>
              </torsional>
              <ode/>
            </friction>
          </surface>
        </collision>
        <visual name='Wall_17_Visual_1'>
          <pose frame=''>2.42119 0 0.25 0 -0 0</pose>
          <geometry>
            <box>
              <size>4.90763 0.15 0.5</size>
            </box>
          </geometry>
          <material>
            <script>
              <uri>file://media/materials/scripts/gazebo.material</uri>
              <name>Gazebo/CeilingTiled</name>
            </script>
            <ambient>0.996078 0.47451 0.0196078 1</ambient>
          </material>
          <meta>
            <layer>0</layer>
          </meta>
        </visual>
        <collision name='Wall_17_Collision_1'>
          <geometry>
            <box>
              <size>4.90763 0.15 0.5</size>
            </box>
          </geometry>
          <pose frame=''>2.42119 0 0.25 0 -0 0</pose>
          <max_contacts>10</max_contacts>
          <surface>
            <contact>
              <ode/>
            </contact>
            <bounce/>
            <friction>
              <torsional>
                <ode/>
              </torsional>
              <ode/>
            </friction>
          </surface>
        </collision>
        <visual name='Wall_17_Visual_2'>
          <pose frame=''>2.82119 0 1.5 0 -0 0</pose>
          <geometry>
            <box>
              <size>4.10763 0.15 2</size>
            </box>
          </geometry>
          <material>
            <script>
              <uri>file://media/materials/scripts/gazebo.material</uri>
              <name>Gazebo/CeilingTiled</name>
            </script>
            <ambient>0.996078 0.47451 0.0196078 1</ambient>
          </material>
          <meta>
            <layer>0</layer>
          </meta>
        </visual>
        <collision name='Wall_17_Collision_2'>
          <geometry>
            <box>
              <size>4.10763 0.15 2</size>
            </box>
          </geometry>
          <pose frame=''>2.82119 0 1.5 0 -0 0</pose>
          <max_contacts>10</max_contacts>
          <surface>
            <contact>
              <ode/>
            </contact>
            <bounce/>
            <friction>
              <torsional>
                <ode/>
              </torsional>
              <ode/>
            </friction>
          </surface>
        </collision>
        <visual name='Wall_17_Visual_3'>
          <pose frame=''>0.367371 0 1.9 0 -0 0</pose>
          <geometry>
            <box>
              <size>0.8 0.15 1.2</size>
            </box>
          </geometry>
          <material>
            <script>
              <uri>file://media/materials/scripts/gazebo.material</uri>
              <name>Gazebo/CeilingTiled</name>
            </script>
            <ambient>0.996078 0.47451 0.0196078 1</ambient>
          </material>
          <meta>
            <layer>0</layer>
          </meta>
        </visual>
        <collision name='Wall_17_Collision_3'>
          <geometry>
            <box>
              <size>0.8 0.15 1.2</size>
            </box>
          </geometry>
          <pose frame=''>0.367371 0 1.9 0 -0 0</pose>
          <max_contacts>10</max_contacts>
          <surface>
            <contact>
              <ode/>
            </contact>
            <bounce/>
            <friction>
              <torsional>
                <ode/>
              </torsional>
              <ode/>
            </friction>
          </surface>
        </collision>
        <self_collide>0</self_collide>
        <kinematic>0</kinematic>
      </link>
      <link name='Wall_18'>
        <pose frame=''>0 4.8 0 0 -0 3.14159</pose>
        <visual name='Wall_18_Visual_0'>
          <pose frame=''>-2.45252 0 1.25 0 -0 0</pose>
          <geometry>
            <box>
              <size>4.09496 0.15 2.5</size>
            </box>
          </geometry>
          <material>
            <script>
              <uri>file://media/materials/scripts/gazebo.material</uri>
              <name>Gazebo/CeilingTiled</name>
            </script>
            <ambient>0.996078 0.47451 0.0196078 1</ambient>
          </material>
          <meta>
            <layer>0</layer>
          </meta>
        </visual>
        <collision name='Wall_18_Collision_0'>
          <geometry>
            <box>
              <size>4.09496 0.15 2.5</size>
            </box>
          </geometry>
          <pose frame=''>-2.45252 0 1.25 0 -0 0</pose>
          <max_contacts>10</max_contacts>
          <surface>
            <contact>
              <ode/>
            </contact>
            <bounce/>
            <friction>
              <torsional>
                <ode/>
              </torsional>
              <ode/>
            </friction>
          </surface>
        </collision>
        <visual name='Wall_18_Visual_1'>
          <pose frame=''>2.04748 0 0.25 0 -0 0</pose>
          <geometry>
            <box>
              <size>4.90504 0.15 0.5</size>
            </box>
          </geometry>
          <material>
            <script>
              <uri>file://media/materials/scripts/gazebo.material</uri>
              <name>Gazebo/CeilingTiled</name>
            </script>
            <ambient>0.996078 0.47451 0.0196078 1</ambient>
          </material>
          <meta>
            <layer>0</layer>
          </meta>
        </visual>
        <collision name='Wall_18_Collision_1'>
          <geometry>
            <box>
              <size>4.90504 0.15 0.5</size>
            </box>
          </geometry>
          <pose frame=''>2.04748 0 0.25 0 -0 0</pose>
          <max_contacts>10</max_contacts>
          <surface>
            <contact>
              <ode/>
            </contact>
            <bounce/>
            <friction>
              <torsional>
                <ode/>
              </torsional>
              <ode/>
            </friction>
          </surface>
        </collision>
        <visual name='Wall_18_Visual_2'>
          <pose frame=''>2.44748 0 1.5 0 -0 0</pose>
          <geometry>
            <box>
              <size>4.10504 0.15 2</size>
            </box>
          </geometry>
          <material>
            <script>
              <uri>file://media/materials/scripts/gazebo.material</uri>
              <name>Gazebo/CeilingTiled</name>
            </script>
            <ambient>0.996078 0.47451 0.0196078 1</ambient>
          </material>
          <meta>
            <layer>0</layer>
          </meta>
        </visual>
        <collision name='Wall_18_Collision_2'>
          <geometry>
            <box>
              <size>4.10504 0.15 2</size>
            </box>
          </geometry>
          <pose frame=''>2.44748 0 1.5 0 -0 0</pose>
          <max_contacts>10</max_contacts>
          <surface>
            <contact>
              <ode/>
            </contact>
            <bounce/>
            <friction>
              <torsional>
                <ode/>
              </torsional>
              <ode/>
            </friction>
          </surface>
        </collision>
        <visual name='Wall_18_Visual_3'>
          <pose frame=''>-0.005043 0 1.9 0 -0 0</pose>
          <geometry>
            <box>
              <size>0.8 0.15 1.2</size>
            </box>
          </geometry>
          <material>
            <script>
              <uri>file://media/materials/scripts/gazebo.material</uri>
              <name>Gazebo/CeilingTiled</name>
            </script>
            <ambient>0.996078 0.47451 0.0196078 1</ambient>
          </material>
          <meta>
            <layer>0</layer>
          </meta>
        </visual>
        <collision name='Wall_18_Collision_3'>
          <geometry>
            <box>
              <size>0.8 0.15 1.2</size>
            </box>
          </geometry>
          <pose frame=''>-0.005043 0 1.9 0 -0 0</pose>
          <max_contacts>10</max_contacts>
          <surface>
            <contact>
              <ode/>
            </contact>
            <bounce/>
            <friction>
              <torsional>
                <ode/>
              </torsional>
              <ode/>
            </friction>
          </surface>
        </collision>
        <self_collide>0</self_collide>
        <kinematic>0</kinematic>
      </link>
      <static>1</static>
    </model>
    <state world_name='default'>
      <sim_time>196 120000000</sim_time>
      <real_time>26 597312832</real_time>
      <wall_time>1649509844 81680086</wall_time>
      <iterations>26522</iterations>
      <model name='bookshelf'>
        <pose frame=''>-2.94322 4.33754 0 0 -0 0</pose>
        <scale>1 1 1</scale>
        <model name='bookshelf'>
          <pose frame=''>-2.94322 4.33754 0 0 -0 0</pose>
          <scale>1 1 1</scale>
          <link name='link'>
            <pose frame=''>-2.94322 4.33754 0 0 -0 0</pose>
            <velocity>0 0 0 0 -0 0</velocity>
            <acceleration>0 0 0 0 -0 0</acceleration>
            <wrench>0 0 0 0 -0 0</wrench>
          </link>
        </model>
      </model>
      <model name='ground_plane'>
        <pose frame=''>0 0 0 0 -0 0</pose>
        <scale>1 1 1</scale>
        <link name='link'>
          <pose frame=''>0 0 0 0 -0 0</pose>
          <velocity>0 0 0 0 -0 0</velocity>
          <acceleration>0 0 0 0 -0 0</acceleration>
          <wrench>0 0 0 0 -0 0</wrench>
        </link>
      </model>
      <model name='myrobot'>
        <pose frame=''>-1.63654 -0.315048 0.100027 0 9.7e-05 0.000104</pose>
        <scale>1 1 1</scale>
        <link name='link_1'>
          <pose frame=''>-1.36149 -0.565009 0.1 1.5708 -0 1.5708</pose>
          <velocity>-5.9e-05 -1.2e-05 0.000116 0.000122 -0.000616 -1e-06</velocity>
          <acceleration>-0.115354 -0.026572 0.232908 0.281204 -1.22899 -0.006364</acceleration>
          <wrench>-0.115354 -0.026572 0.232908 0 -0 0</wrench>
        </link>
        <link name='link_1_clone'>
          <pose frame=''>-1.36155 -0.065025 0.1 1.5708 -0 1.5708</pose>
          <velocity>-5.7e-05 -1.2e-05 0.000178 0.000123 -0.000571 -3e-06</velocity>
          <acceleration>-0.110409 -0.026851 0.355993 0.282208 -1.14098 -0.009732</acceleration>
          <wrench>-0.110409 -0.026851 0.355993 0 -0 0</wrench>
        </link>
        <link name='link_1_clone_0'>
          <pose frame=''>-1.91159 -0.065082 0.1 1.5708 -0 1.5708</pose>
          <velocity>-4.2e-05 -1.2e-05 0.003748 0.000121 -0.000421 -7e-06</velocity>
          <acceleration>-0.097107 -0.021721 7.49611 0.280715 -0.84344 -0.012302</acceleration>
          <wrench>-0.097107 -0.021721 7.49611 0 -0 0</wrench>
        </link>
        <link name='link_1_clone_1'>
          <pose frame=''>-1.91154 -0.565077 0.1 1.5708 -0 1.5708</pose>
          <velocity>-5.5e-05 -1.2e-05 0.003688 0.000121 -0.000547 -8e-06</velocity>
          <acceleration>-0.112607 -0.021701 7.37556 0.280523 -1.09497 -0.013604</acceleration>
          <wrench>-0.112607 -0.021701 7.37556 0 -0 0</wrench>
        </link>
        <link name='link_2'>
          <pose frame=''>-1.63654 -0.31505 0.1 0 -0 0.000104</pose>
          <velocity>-4.4e-05 -1.2e-05 0.001934 0.000121 0.006493 0</velocity>
          <acceleration>-0.094873 -0.023854 3.86734 0.241318 0.417845 -0.007071</acceleration>
          <wrench>-0.094873 -0.023854 3.86734 0 -0 0</wrench>
        </link>
      </model>
      <model name='myroom'>
        <pose frame=''>-0.21045 -0.363534 0 0 -0 0</pose>
        <scale>1 1 1</scale>
        <link name='Wall_15'>
          <pose frame=''>-4.63545 -0.363534 0 0 0 -1.5708</pose>
          <velocity>0 0 0 0 -0 0</velocity>
          <acceleration>0 0 0 0 -0 0</acceleration>
          <wrench>0 0 0 0 -0 0</wrench>
        </link>
        <link name='Wall_16'>
          <pose frame=''>-0.210452 -5.16353 0 0 -0 0</pose>
          <velocity>0 0 0 0 -0 0</velocity>
          <acceleration>0 0 0 0 -0 0</acceleration>
          <wrench>0 0 0 0 -0 0</wrench>
        </link>
        <link name='Wall_17'>
          <pose frame=''>4.21455 -0.363534 0 0 -0 1.5708</pose>
          <velocity>0 0 0 0 -0 0</velocity>
          <acceleration>0 0 0 0 -0 0</acceleration>
          <wrench>0 0 0 0 -0 0</wrench>
        </link>
        <link name='Wall_18'>
          <pose frame=''>-0.210452 4.43647 0 0 -0 3.14159</pose>
          <velocity>0 0 0 0 -0 0</velocity>
          <acceleration>0 0 0 0 -0 0</acceleration>
          <wrench>0 0 0 0 -0 0</wrench>
        </link>
      </model>
      <model name='table_marble'>
        <pose frame=''>0.7435 1.02198 0.648 0 -0 0</pose>
        <scale>1 1 1</scale>
        <model name='table_marble'>
          <pose frame=''>0.7435 1.02198 0.648 0 -0 0</pose>
          <scale>1 1 1</scale>
          <link name='link'>
            <pose frame=''>0.7435 1.02198 0.648 0 -0 0</pose>
            <velocity>0 0 0 0 -0 0</velocity>
            <acceleration>0 0 0 0 -0 0</acceleration>
            <wrench>0 0 0 0 -0 0</wrench>
          </link>
        </model>
      </model>
      <light name='sun'>
        <pose frame=''>0 0 10 0 -0 0</pose>
      </light>
    </state>
    <model name='myrobot'>
      <link name='link_1'>
        <pose frame=''>0.275023 -0.249989 0 1.5707 0 1.5707</pose>
        <inertial>
          <mass>1</mass>
          <inertia>
            <ixx>0.145833</ixx>
            <ixy>0</ixy>
            <ixz>0</ixz>
            <iyy>0.145833</iyy>
            <iyz>0</iyz>
            <izz>0.125</izz>
          </inertia>
          <pose frame=''>0 0 0 0 -0 0</pose>
        </inertial>
        <gravity>1</gravity>
        <self_collide>0</self_collide>
        <kinematic>0</kinematic>
        <visual name='visual'>
          <pose frame=''>0 0 0 0 -0 0</pose>
          <geometry>
            <cylinder>
              <radius>0.1</radius>
              <length>0.05</length>
            </cylinder>
          </geometry>
          <material>
            <lighting>1</lighting>
            <script>
              <uri>file://media/materials/scripts/gazebo.material</uri>
              <name>Gazebo/Grey</name>
            </script>
            <shader type='pixel'>
              <normal_map>__default__</normal_map>
            </shader>
            <ambient>0.3 0.3 0.3 1</ambient>
            <diffuse>0.7 0.7 0.7 1</diffuse>
            <specular>0.01 0.01 0.01 1</specular>
            <emissive>0 0 0 1</emissive>
          </material>
          <transparency>0</transparency>
          <cast_shadows>1</cast_shadows>
        </visual>
        <collision name='collision'>
          <laser_retro>0</laser_retro>
          <max_contacts>10</max_contacts>
          <pose frame=''>0 0 0 0 -0 0</pose>
          <geometry>
            <cylinder>
              <radius>0.1</radius>
              <length>0.05</length>
            </cylinder>
          </geometry>
          <surface>
            <friction>
              <ode>
                <mu>1</mu>
                <mu2>1</mu2>
                <fdir1>0 0 0</fdir1>
                <slip1>0</slip1>
                <slip2>0</slip2>
              </ode>
              <torsional>
                <coefficient>1</coefficient>
                <patch_radius>0</patch_radius>
                <surface_radius>0</surface_radius>
                <use_patch_radius>1</use_patch_radius>
                <ode>
                  <slip>0</slip>
                </ode>
              </torsional>
            </friction>
            <bounce>
              <restitution_coefficient>0</restitution_coefficient>
              <threshold>1e+06</threshold>
            </bounce>
            <contact>
              <collide_without_contact>0</collide_without_contact>
              <collide_without_contact_bitmask>1</collide_without_contact_bitmask>
              <collide_bitmask>1</collide_bitmask>
              <ode>
                <soft_cfm>0</soft_cfm>
                <soft_erp>0.2</soft_erp>
                <kp>1e+13</kp>
                <kd>1</kd>
                <max_vel>0.01</max_vel>
                <min_depth>0</min_depth>
              </ode>
              <bullet>
                <split_impulse>1</split_impulse>
                <split_impulse_penetration_threshold>-0.01</split_impulse_penetration_threshold>
                <soft_cfm>0</soft_cfm>
                <soft_erp>0.2</soft_erp>
                <kp>1e+13</kp>
                <kd>1</kd>
              </bullet>
            </contact>
          </surface>
        </collision>
      </link>
      <link name='link_1_clone'>
        <pose frame=''>0.275019 0.249995 0 1.5707 0 1.5707</pose>
        <inertial>
          <mass>1</mass>
          <inertia>
            <ixx>0.145833</ixx>
            <ixy>0</ixy>
            <ixz>0</ixz>
            <iyy>0.145833</iyy>
            <iyz>0</iyz>
            <izz>0.125</izz>
          </inertia>
          <pose frame=''>0 0 0 0 -0 0</pose>
        </inertial>
        <self_collide>0</self_collide>
        <kinematic>0</kinematic>
        <gravity>1</gravity>
        <visual name='visual'>
          <pose frame=''>0 0 0 0 -0 0</pose>
          <geometry>
            <cylinder>
              <radius>0.1</radius>
              <length>0.05</length>
            </cylinder>
          </geometry>
          <material>
            <lighting>1</lighting>
            <script>
              <uri>file://media/materials/scripts/gazebo.material</uri>
              <name>Gazebo/Grey</name>
            </script>
            <shader type='pixel'>
              <normal_map>__default__</normal_map>
            </shader>
            <ambient>0.3 0.3 0.3 1</ambient>
            <diffuse>0.7 0.7 0.7 1</diffuse>
            <specular>0.01 0.01 0.01 1</specular>
            <emissive>0 0 0 1</emissive>
          </material>
          <transparency>0</transparency>
          <cast_shadows>1</cast_shadows>
        </visual>
        <collision name='collision'>
          <laser_retro>0</laser_retro>
          <max_contacts>10</max_contacts>
          <pose frame=''>0 0 0 0 -0 0</pose>
          <geometry>
            <cylinder>
              <radius>0.1</radius>
              <length>0.05</length>
            </cylinder>
          </geometry>
          <surface>
            <friction>
              <ode>
                <mu>1</mu>
                <mu2>1</mu2>
                <fdir1>0 0 0</fdir1>
                <slip1>0</slip1>
                <slip2>0</slip2>
              </ode>
              <torsional>
                <coefficient>1</coefficient>
                <patch_radius>0</patch_radius>
                <surface_radius>0</surface_radius>
                <use_patch_radius>1</use_patch_radius>
                <ode>
                  <slip>0</slip>
                </ode>
              </torsional>
            </friction>
            <bounce>
              <restitution_coefficient>0</restitution_coefficient>
              <threshold>1e+06</threshold>
            </bounce>
            <contact>
              <collide_without_contact>0</collide_without_contact>
              <collide_without_contact_bitmask>1</collide_without_contact_bitmask>
              <collide_bitmask>1</collide_bitmask>
              <ode>
                <soft_cfm>0</soft_cfm>
                <soft_erp>0.2</soft_erp>
                <kp>1e+13</kp>
                <kd>1</kd>
                <max_vel>0.01</max_vel>
                <min_depth>0</min_depth>
              </ode>
              <bullet>
                <split_impulse>1</split_impulse>
                <split_impulse_penetration_threshold>-0.01</split_impulse_penetration_threshold>
                <soft_cfm>0</soft_cfm>
                <soft_erp>0.2</soft_erp>
                <kp>1e+13</kp>
                <kd>1</kd>
              </bullet>
            </contact>
          </surface>
        </collision>
      </link>
      <link name='link_1_clone_0'>
        <pose frame=''>-0.27502 0.249995 0 1.5707 0 1.5707</pose>
        <inertial>
          <mass>1</mass>
          <inertia>
            <ixx>0.145833</ixx>
            <ixy>0</ixy>
            <ixz>0</ixz>
            <iyy>0.145833</iyy>
            <iyz>0</iyz>
            <izz>0.125</izz>
          </inertia>
          <pose frame=''>0 0 0 0 -0 0</pose>
        </inertial>
        <self_collide>0</self_collide>
        <kinematic>0</kinematic>
        <gravity>1</gravity>
        <visual name='visual'>
          <pose frame=''>0 0 0 0 -0 0</pose>
          <geometry>
            <cylinder>
              <radius>0.1</radius>
              <length>0.05</length>
            </cylinder>
          </geometry>
          <material>
            <lighting>1</lighting>
            <script>
              <uri>file://media/materials/scripts/gazebo.material</uri>
              <name>Gazebo/Grey</name>
            </script>
            <shader type='pixel'>
              <normal_map>__default__</normal_map>
            </shader>
            <ambient>0.3 0.3 0.3 1</ambient>
            <diffuse>0.7 0.7 0.7 1</diffuse>
            <specular>0.01 0.01 0.01 1</specular>
            <emissive>0 0 0 1</emissive>
          </material>
          <transparency>0</transparency>
          <cast_shadows>1</cast_shadows>
        </visual>
        <collision name='collision'>
          <laser_retro>0</laser_retro>
          <max_contacts>10</max_contacts>
          <pose frame=''>0 0 0 0 -0 0</pose>
          <geometry>
            <cylinder>
              <radius>0.1</radius>
              <length>0.05</length>
            </cylinder>
          </geometry>
          <surface>
            <friction>
              <ode>
                <mu>1</mu>
                <mu2>1</mu2>
                <fdir1>0 0 0</fdir1>
                <slip1>0</slip1>
                <slip2>0</slip2>
              </ode>
              <torsional>
                <coefficient>1</coefficient>
                <patch_radius>0</patch_radius>
                <surface_radius>0</surface_radius>
                <use_patch_radius>1</use_patch_radius>
                <ode>
                  <slip>0</slip>
                </ode>
              </torsional>
            </friction>
            <bounce>
              <restitution_coefficient>0</restitution_coefficient>
              <threshold>1e+06</threshold>
            </bounce>
            <contact>
              <collide_without_contact>0</collide_without_contact>
              <collide_without_contact_bitmask>1</collide_without_contact_bitmask>
              <collide_bitmask>1</collide_bitmask>
              <ode>
                <soft_cfm>0</soft_cfm>
                <soft_erp>0.2</soft_erp>
                <kp>1e+13</kp>
                <kd>1</kd>
                <max_vel>0.01</max_vel>
                <min_depth>0</min_depth>
              </ode>
              <bullet>
                <split_impulse>1</split_impulse>
                <split_impulse_penetration_threshold>-0.01</split_impulse_penetration_threshold>
                <soft_cfm>0</soft_cfm>
                <soft_erp>0.2</soft_erp>
                <kp>1e+13</kp>
                <kd>1</kd>
              </bullet>
            </contact>
          </surface>
        </collision>
      </link>
      <link name='link_1_clone_1'>
        <pose frame=''>-0.27502 -0.25 0 1.5707 0 1.5707</pose>
        <inertial>
          <mass>1</mass>
          <inertia>
            <ixx>0.145833</ixx>
            <ixy>0</ixy>
            <ixz>0</ixz>
            <iyy>0.145833</iyy>
            <iyz>0</iyz>
            <izz>0.125</izz>
          </inertia>
          <pose frame=''>0 0 0 0 -0 0</pose>
        </inertial>
        <self_collide>0</self_collide>
        <kinematic>0</kinematic>
        <gravity>1</gravity>
        <visual name='visual'>
          <pose frame=''>0 0 0 0 -0 0</pose>
          <geometry>
            <cylinder>
              <radius>0.1</radius>
              <length>0.05</length>
            </cylinder>
          </geometry>
          <material>
            <lighting>1</lighting>
            <script>
              <uri>file://media/materials/scripts/gazebo.material</uri>
              <name>Gazebo/Grey</name>
            </script>
            <shader type='pixel'>
              <normal_map>__default__</normal_map>
            </shader>
            <ambient>0.3 0.3 0.3 1</ambient>
            <diffuse>0.7 0.7 0.7 1</diffuse>
            <specular>0.01 0.01 0.01 1</specular>
            <emissive>0 0 0 1</emissive>
          </material>
          <transparency>0</transparency>
          <cast_shadows>1</cast_shadows>
        </visual>
        <collision name='collision'>
          <laser_retro>0</laser_retro>
          <max_contacts>10</max_contacts>
          <pose frame=''>0 0 0 0 -0 0</pose>
          <geometry>
            <cylinder>
              <radius>0.1</radius>
              <length>0.05</length>
            </cylinder>
          </geometry>
          <surface>
            <friction>
              <ode>
                <mu>1</mu>
                <mu2>1</mu2>
                <fdir1>0 0 0</fdir1>
                <slip1>0</slip1>
                <slip2>0</slip2>
              </ode>
              <torsional>
                <coefficient>1</coefficient>
                <patch_radius>0</patch_radius>
                <surface_radius>0</surface_radius>
                <use_patch_radius>1</use_patch_radius>
                <ode>
                  <slip>0</slip>
                </ode>
              </torsional>
            </friction>
            <bounce>
              <restitution_coefficient>0</restitution_coefficient>
              <threshold>1e+06</threshold>
            </bounce>
            <contact>
              <collide_without_contact>0</collide_without_contact>
              <collide_without_contact_bitmask>1</collide_without_contact_bitmask>
              <collide_bitmask>1</collide_bitmask>
              <ode>
                <soft_cfm>0</soft_cfm>
                <soft_erp>0.2</soft_erp>
                <kp>1e+13</kp>
                <kd>1</kd>
                <max_vel>0.01</max_vel>
                <min_depth>0</min_depth>
              </ode>
              <bullet>
                <split_impulse>1</split_impulse>
                <split_impulse_penetration_threshold>-0.01</split_impulse_penetration_threshold>
                <soft_cfm>0</soft_cfm>
                <soft_erp>0.2</soft_erp>
                <kp>1e+13</kp>
                <kd>1</kd>
              </bullet>
            </contact>
          </surface>
        </collision>
      </link>
      <link name='link_2'>
        <pose frame=''>-0 -2e-06 0 0 -0 0</pose>
        <inertial>
          <mass>1</mass>
          <inertia>
            <ixx>0.166667</ixx>
            <ixy>0</ixy>
            <ixz>0</ixz>
            <iyy>0.166667</iyy>
            <iyz>0</iyz>
            <izz>0.166667</izz>
          </inertia>
          <pose frame=''>0 0 0 0 -0 0</pose>
        </inertial>
        <gravity>1</gravity>
        <self_collide>0</self_collide>
        <kinematic>0</kinematic>
        <visual name='visual'>
          <pose frame=''>0 0 0 0 -0 0</pose>
          <geometry>
            <box>
              <size>0.5 0.7 0.1</size>
            </box>
          </geometry>
          <material>
            <lighting>1</lighting>
            <script>
              <uri>file://media/materials/scripts/gazebo.material</uri>
              <name>Gazebo/Grey</name>
            </script>
            <shader type='pixel'>
              <normal_map>__default__</normal_map>
            </shader>
            <ambient>0.3 0.3 0.3 1</ambient>
            <diffuse>0.7 0.7 0.7 1</diffuse>
            <specular>0.01 0.01 0.01 1</specular>
            <emissive>0 0 0 1</emissive>
          </material>
          <transparency>0</transparency>
          <cast_shadows>1</cast_shadows>
        </visual>
        <collision name='collision'>
          <laser_retro>0</laser_retro>
          <max_contacts>10</max_contacts>
          <pose frame=''>0 0 0 0 -0 0</pose>
          <geometry>
            <box>
              <size>0.5 0.7 0.1</size>
            </box>
          </geometry>
          <surface>
            <friction>
              <ode>
                <mu>1</mu>
                <mu2>1</mu2>
                <fdir1>0 0 0</fdir1>
                <slip1>0</slip1>
                <slip2>0</slip2>
              </ode>
              <torsional>
                <coefficient>1</coefficient>
                <patch_radius>0</patch_radius>
                <surface_radius>0</surface_radius>
                <use_patch_radius>1</use_patch_radius>
                <ode>
                  <slip>0</slip>
                </ode>
              </torsional>
            </friction>
            <bounce>
              <restitution_coefficient>0</restitution_coefficient>
              <threshold>1e+06</threshold>
            </bounce>
            <contact>
              <collide_without_contact>0</collide_without_contact>
              <collide_without_contact_bitmask>1</collide_without_contact_bitmask>
              <collide_bitmask>1</collide_bitmask>
              <ode>
                <soft_cfm>0</soft_cfm>
                <soft_erp>0.2</soft_erp>
                <kp>1e+13</kp>
                <kd>1</kd>
                <max_vel>0.01</max_vel>
                <min_depth>0</min_depth>
              </ode>
              <bullet>
                <split_impulse>1</split_impulse>
                <split_impulse_penetration_threshold>-0.01</split_impulse_penetration_threshold>
                <soft_cfm>0</soft_cfm>
                <soft_erp>0.2</soft_erp>
                <kp>1e+13</kp>
                <kd>1</kd>
              </bullet>
            </contact>
          </surface>
        </collision>
      </link>
      <joint name='link_2_JOINT_10' type='revolute'>
        <parent>link_2</parent>
        <child>link_1</child>
        <pose frame=''>0 0 0 0 -0 0</pose>
        <axis>
          <xyz>1 0 0</xyz>
          <use_parent_model_frame>0</use_parent_model_frame>
          <limit>
            <lower>-1.79769e+308</lower>
            <upper>1.79769e+308</upper>
            <effort>-1</effort>
            <velocity>-1</velocity>
          </limit>
          <dynamics>
            <spring_reference>0</spring_reference>
            <spring_stiffness>0</spring_stiffness>
            <damping>0</damping>
          </dynamics>
        </axis>
        <physics>
          <ode>
            <limit>
              <cfm>0</cfm>
              <erp>0.2</erp>
            </limit>
            <suspension>
              <cfm>0</cfm>
              <erp>0.2</erp>
            </suspension>
          </ode>
        </physics>
      </joint>
      <joint name='link_2_JOINT_11' type='revolute'>
        <parent>link_2</parent>
        <child>link_1_clone_0</child>
        <pose frame=''>0 0 0 0 -0 0</pose>
        <axis>
          <xyz>1 0 0</xyz>
          <use_parent_model_frame>0</use_parent_model_frame>
          <limit>
            <lower>-1.79769e+308</lower>
            <upper>1.79769e+308</upper>
            <effort>-1</effort>
            <velocity>-1</velocity>
          </limit>
          <dynamics>
            <spring_reference>0</spring_reference>
            <spring_stiffness>0</spring_stiffness>
            <damping>0</damping>
          </dynamics>
        </axis>
        <physics>
          <ode>
            <limit>
              <cfm>0</cfm>
              <erp>0.2</erp>
            </limit>
            <suspension>
              <cfm>0</cfm>
              <erp>0.2</erp>
            </suspension>
          </ode>
        </physics>
      </joint>
      <joint name='link_2_JOINT_12' type='revolute'>
        <parent>link_2</parent>
        <child>link_1_clone_1</child>
        <pose frame=''>0 0 0 0 -0 0</pose>
        <axis>
          <xyz>1 0 0</xyz>
          <use_parent_model_frame>0</use_parent_model_frame>
          <limit>
            <lower>-1.79769e+308</lower>
            <upper>1.79769e+308</upper>
            <effort>-1</effort>
            <velocity>-1</velocity>
          </limit>
          <dynamics>
            <spring_reference>0</spring_reference>
            <spring_stiffness>0</spring_stiffness>
            <damping>0</damping>
          </dynamics>
        </axis>
        <physics>
          <ode>
            <limit>
              <cfm>0</cfm>
              <erp>0.2</erp>
            </limit>
            <suspension>
              <cfm>0</cfm>
              <erp>0.2</erp>
            </suspension>
          </ode>
        </physics>
      </joint>
      <joint name='link_2_JOINT_3' type='revolute'>
        <parent>link_2</parent>
        <child>link_1</child>
        <pose frame=''>0 0 0 0 -0 0</pose>
        <axis>
          <xyz>1 0 0</xyz>
          <use_parent_model_frame>0</use_parent_model_frame>
          <limit>
            <lower>-1.79769e+308</lower>
            <upper>1.79769e+308</upper>
            <effort>-1</effort>
            <velocity>-1</velocity>
          </limit>
          <dynamics>
            <spring_reference>0</spring_reference>
            <spring_stiffness>0</spring_stiffness>
            <damping>0</damping>
          </dynamics>
        </axis>
        <physics>
          <ode>
            <limit>
              <cfm>0</cfm>
              <erp>0.2</erp>
            </limit>
            <suspension>
              <cfm>0</cfm>
              <erp>0.2</erp>
            </suspension>
          </ode>
        </physics>
      </joint>
      <joint name='link_2_JOINT_4' type='revolute'>
        <parent>link_2</parent>
        <child>link_1_clone</child>
        <pose frame=''>0 0 0 0 -0 0</pose>
        <axis>
          <xyz>1 0 0</xyz>
          <use_parent_model_frame>0</use_parent_model_frame>
          <limit>
            <lower>-1.79769e+308</lower>
            <upper>1.79769e+308</upper>
            <effort>-1</effort>
            <velocity>-1</velocity>
          </limit>
          <dynamics>
            <spring_reference>0</spring_reference>
            <spring_stiffness>0</spring_stiffness>
            <damping>0</damping>
          </dynamics>
        </axis>
        <physics>
          <ode>
            <limit>
              <cfm>0</cfm>
              <erp>0.2</erp>
            </limit>
            <suspension>
              <cfm>0</cfm>
              <erp>0.2</erp>
            </suspension>
          </ode>
        </physics>
      </joint>
      <joint name='link_2_JOINT_5' type='revolute'>
        <parent>link_2</parent>
        <child>link_1_clone_0</child>
        <pose frame=''>0 0 0 0 -0 0</pose>
        <axis>
          <xyz>1 0 0</xyz>
          <use_parent_model_frame>0</use_parent_model_frame>
          <limit>
            <lower>-1.79769e+308</lower>
            <upper>1.79769e+308</upper>
            <effort>-1</effort>
            <velocity>-1</velocity>
          </limit>
          <dynamics>
            <spring_reference>0</spring_reference>
            <spring_stiffness>0</spring_stiffness>
            <damping>0</damping>
          </dynamics>
        </axis>
        <physics>
          <ode>
            <limit>
              <cfm>0</cfm>
              <erp>0.2</erp>
            </limit>
            <suspension>
              <cfm>0</cfm>
              <erp>0.2</erp>
            </suspension>
          </ode>
        </physics>
      </joint>
      <joint name='link_2_JOINT_6' type='revolute'>
        <parent>link_2</parent>
        <child>link_1_clone_1</child>
        <pose frame=''>0 0 0 0 -0 0</pose>
        <axis>
          <xyz>1 0 0</xyz>
          <use_parent_model_frame>0</use_parent_model_frame>
          <limit>
            <lower>-1.79769e+308</lower>
            <upper>1.79769e+308</upper>
            <effort>-1</effort>
            <velocity>-1</velocity>
          </limit>
          <dynamics>
            <spring_reference>0</spring_reference>
            <spring_stiffness>0</spring_stiffness>
            <damping>0</damping>
          </dynamics>
        </axis>
        <physics>
          <ode>
            <limit>
              <cfm>0</cfm>
              <erp>0.2</erp>
            </limit>
            <suspension>
              <cfm>0</cfm>
              <erp>0.2</erp>
            </suspension>
          </ode>
        </physics>
      </joint>
      <joint name='link_2_JOINT_7' type='revolute'>
        <parent>link_2</parent>
        <child>link_1_clone_1</child>
        <pose frame=''>0 0 0 0 -0 0</pose>
        <axis>
          <xyz>1 0 0</xyz>
          <use_parent_model_frame>0</use_parent_model_frame>
          <limit>
            <lower>-1.79769e+308</lower>
            <upper>1.79769e+308</upper>
            <effort>-1</effort>
            <velocity>-1</velocity>
          </limit>
          <dynamics>
            <spring_reference>0</spring_reference>
            <spring_stiffness>0</spring_stiffness>
            <damping>0</damping>
          </dynamics>
        </axis>
        <physics>
          <ode>
            <limit>
              <cfm>0</cfm>
              <erp>0.2</erp>
            </limit>
            <suspension>
              <cfm>0</cfm>
              <erp>0.2</erp>
            </suspension>
          </ode>
        </physics>
      </joint>
      <joint name='link_2_JOINT_9' type='revolute'>
        <parent>link_2</parent>
        <child>link_1_clone</child>
        <pose frame=''>0 0 0 0 -0 0</pose>
        <axis>
          <xyz>1 0 0</xyz>
          <use_parent_model_frame>0</use_parent_model_frame>
          <limit>
            <lower>-1.79769e+308</lower>
            <upper>1.79769e+308</upper>
            <effort>-1</effort>
            <velocity>-1</velocity>
          </limit>
          <dynamics>
            <spring_reference>0</spring_reference>
            <spring_stiffness>0</spring_stiffness>
            <damping>0</damping>
          </dynamics>
        </axis>
        <physics>
          <ode>
            <limit>
              <cfm>0</cfm>
              <erp>0.2</erp>
            </limit>
            <suspension>
              <cfm>0</cfm>
              <erp>0.2</erp>
            </suspension>
          </ode>
        </physics>
      </joint>
      <static>0</static>
      <allow_auto_disable>1</allow_auto_disable>
      <pose frame=''>-1.17801 -0.45897 0.2 0 -0 0</pose>
    </model>
    <gui fullscreen='0'>
      <camera name='user_camera'>
        <pose frame=''>1.03793 -11.6808 7.18114 0 0.623519 1.68158</pose>
        <view_controller>orbit</view_controller>
        <projection_type>perspective</projection_type>
      </camera>
    </gui>
    <model name='bookshelf'>
      <model name='bookshelf'>
        <static>1</static>
        <link name='link'>
          <inertial>
            <mass>1</mass>
          </inertial>
          <collision name='back'>
            <pose frame=''>0 0.005 0.6 0 -0 0</pose>
            <geometry>
              <box>
                <size>0.9 0.01 1.2</size>
              </box>
            </geometry>
            <max_contacts>10</max_contacts>
            <surface>
              <contact>
                <ode/>
              </contact>
              <bounce/>
              <friction>
                <torsional>
                  <ode/>
                </torsional>
                <ode/>
              </friction>
            </surface>
          </collision>
          <visual name='visual1'>
            <pose frame=''>0 0.005 0.6 0 -0 0</pose>
            <geometry>
              <box>
                <size>0.9 0.01 1.2</size>
              </box>
            </geometry>
            <material>
              <script>
                <uri>file://media/materials/scripts/gazebo.material</uri>
                <name>Gazebo/Wood</name>
              </script>
            </material>
          </visual>
          <collision name='left_side'>
            <pose frame=''>0.45 -0.195 0.6 0 -0 0</pose>
            <geometry>
              <box>
                <size>0.02 0.4 1.2</size>
              </box>
            </geometry>
            <max_contacts>10</max_contacts>
            <surface>
              <contact>
                <ode/>
              </contact>
              <bounce/>
              <friction>
                <torsional>
                  <ode/>
                </torsional>
                <ode/>
              </friction>
            </surface>
          </collision>
          <visual name='visual2'>
            <pose frame=''>0.45 -0.195 0.6 0 -0 0</pose>
            <geometry>
              <box>
                <size>0.02 0.4 1.2</size>
              </box>
            </geometry>
            <material>
              <script>
                <uri>file://media/materials/scripts/gazebo.material</uri>
                <name>Gazebo/Wood</name>
              </script>
            </material>
          </visual>
          <collision name='right_side'>
            <pose frame=''>-0.45 -0.195 0.6 0 -0 0</pose>
            <geometry>
              <box>
                <size>0.02 0.4 1.2</size>
              </box>
            </geometry>
            <max_contacts>10</max_contacts>
            <surface>
              <contact>
                <ode/>
              </contact>
              <bounce/>
              <friction>
                <torsional>
                  <ode/>
                </torsional>
                <ode/>
              </friction>
            </surface>
          </collision>
          <visual name='visual3'>
            <pose frame=''>-0.45 -0.195 0.6 0 -0 0</pose>
            <geometry>
              <box>
                <size>0.02 0.4 1.2</size>
              </box>
            </geometry>
            <material>
              <script>
                <uri>file://media/materials/scripts/gazebo.material</uri>
                <name>Gazebo/Wood</name>
              </script>
            </material>
          </visual>
          <collision name='bottom'>
            <pose frame=''>0 -0.195 0.03 0 -0 0</pose>
            <geometry>
              <box>
                <size>0.88 0.4 0.06</size>
              </box>
            </geometry>
            <max_contacts>10</max_contacts>
            <surface>
              <contact>
                <ode/>
              </contact>
              <bounce/>
              <friction>
                <torsional>
                  <ode/>
                </torsional>
                <ode/>
              </friction>
            </surface>
          </collision>
          <visual name='visual4'>
            <pose frame=''>0 -0.195 0.03 0 -0 0</pose>
            <geometry>
              <box>
                <size>0.88 0.4 0.06</size>
              </box>
            </geometry>
            <material>
              <script>
                <uri>file://media/materials/scripts/gazebo.material</uri>
                <name>Gazebo/Wood</name>
              </script>
            </material>
          </visual>
          <collision name='top'>
            <pose frame=''>0 -0.195 1.19 0 -0 0</pose>
            <geometry>
              <box>
                <size>0.88 0.4 0.02</size>
              </box>
            </geometry>
            <max_contacts>10</max_contacts>
            <surface>
              <contact>
                <ode/>
              </contact>
              <bounce/>
              <friction>
                <torsional>
                  <ode/>
                </torsional>
                <ode/>
              </friction>
            </surface>
          </collision>
          <visual name='visual5'>
            <pose frame=''>0 -0.195 1.19 0 -0 0</pose>
            <geometry>
              <box>
                <size>0.88 0.4 0.02</size>
              </box>
            </geometry>
            <material>
              <script>
                <uri>file://media/materials/scripts/gazebo.material</uri>
                <name>Gazebo/Wood</name>
              </script>
            </material>
          </visual>
          <collision name='low_shelf'>
            <pose frame=''>0 -0.195 0.43 0 -0 0</pose>
            <geometry>
              <box>
                <size>0.88 0.4 0.02</size>
              </box>
            </geometry>
            <max_contacts>10</max_contacts>
            <surface>
              <contact>
                <ode/>
              </contact>
              <bounce/>
              <friction>
                <torsional>
                  <ode/>
                </torsional>
                <ode/>
              </friction>
            </surface>
          </collision>
          <visual name='visual6'>
            <pose frame=''>0 -0.195 0.43 0 -0 0</pose>
            <geometry>
              <box>
                <size>0.88 0.4 0.02</size>
              </box>
            </geometry>
            <material>
              <script>
                <uri>file://media/materials/scripts/gazebo.material</uri>
                <name>Gazebo/Wood</name>
              </script>
            </material>
          </visual>
          <collision name='high_shelf'>
            <pose frame=''>0 -0.195 0.8 0 -0 0</pose>
            <geometry>
              <box>
                <size>0.88 0.4 0.02</size>
              </box>
            </geometry>
            <max_contacts>10</max_contacts>
            <surface>
              <contact>
                <ode/>
              </contact>
              <bounce/>
              <friction>
                <torsional>
                  <ode/>
                </torsional>
                <ode/>
              </friction>
            </surface>
          </collision>
          <visual name='visual7'>
            <pose frame=''>0 -0.195 0.8 0 -0 0</pose>
            <geometry>
              <box>
                <size>0.88 0.4 0.02</size>
              </box>
            </geometry>
            <material>
              <script>
                <uri>file://media/materials/scripts/gazebo.material</uri>
                <name>Gazebo/Wood</name>
              </script>
            </material>
          </visual>
          <self_collide>0</self_collide>
          <kinematic>0</kinematic>
        </link>
        <pose frame=''>-1e-06 -2e-06 0 0 -0 0</pose>
      </model>
      <static>0</static>
      <allow_auto_disable>1</allow_auto_disable>
      <pose frame=''>-2.94322 4.33754 0 0 -0 0</pose>
    </model>
    <model name='table_marble'>
      <model name='table_marble'>
        <static>1</static>
        <pose frame=''>0 -5e-06 0 0 -0 0</pose>
        <link name='link'>
          <collision name='collision'>
            <geometry>
              <mesh>
                <uri>model:///table_marble/meshes/table_lightmap.dae</uri>
                <scale>0.25 0.25 0.25</scale>
              </mesh>
            </geometry>
            <max_contacts>10</max_contacts>
            <surface>
              <contact>
                <ode/>
              </contact>
              <bounce/>
              <friction>
                <torsional>
                  <ode/>
                </torsional>
                <ode/>
              </friction>
            </surface>
          </collision>
          <visual name='visual'>
            <geometry>
              <mesh>
                <uri>model://table_marble/meshes/table_lightmap.dae</uri>
                <scale>0.25 0.25 0.25</scale>
              </mesh>
            </geometry>
            <material>
              <script>
                <uri>model://table_marble/materials/scripts</uri>
                <uri>model://table_marble/materials/textures</uri>
                <name>Table/Marble_Lightmap</name>
              </script>
              <lighting>0</lighting>
            </material>
          </visual>
          <self_collide>0</self_collide>
          <kinematic>0</kinematic>
        </link>
      </model>
      <static>0</static>
      <allow_auto_disable>1</allow_auto_disable>
      <pose frame=''>0.7435 1.02198 0.648 0 -0 0</pose>
    </model>
  </world>
</sdf>
